Workbook
Name a: Tabela_de_categorias_e_funcionários[[#Headers],[Aprovações]]
Name a: Tabela_de_categorias_e_funcionários[[#Headers],[Aprovações]]
Name Arcangelo: Tabela_de_categorias_e_funcionários[[#Headers],[Aprovações]]
Name Arcangelo: Tabela_de_categorias_e_funcionários[[#Headers],[Aprovações]]
Name Arcangelo: Tabela_de_categorias_e_funcionários[[#Headers],[Aprovações]]
Name Arcangelo: Tabela_de_categorias_e_funcionários[[#Headers],[Aprovações]]
Name Arcangelo: Tabela_de_categorias_e_funcionários[[#Headers],[Aprovações]]
Name Arcangelo: Tabela_de_categorias_e_funcionários[[#Headers],[Aprovações]]
Name Arcangelo: Tabela_de_categorias_e_funcionários[[#Headers],[Aprovações]]
Name Arcangelo: Tabela_de_categorias_e_funcionários[[#Headers],[Aprovações]]
Name Arcangelo: Tabela_de_categorias_e_funcionários[[#Headers],[Aprovações]]
Name Biopark: Tabela_de_categorias_e_funcionários[[#Headers],[Aprovações]]
Name Categoria_Lista: Configuração!$B$5:$B$11
Name ColumnTitle1: 'Prot. CVEL - Altona'!$B$4
Name ColumnTitle1: 'Prot. CVEL - Bella Citta'!$B$4
Name ColumnTitle1: 'Prot. CVEL - Bresolin'!$B$4
Name ColumnTitle1: 'Prot. TLD - 13 de Abril'!$B$4
Name ColumnTitle1: 'Prot. TLD - Biopark'!$B$4
Name ColumnTitle1: 'Prot. TLD - Carmel'!$B$4
Name ColumnTitle1: 'Prot. TLD - Horizont'!$B$4
Name ColumnTitle1: 'Prot. TLD - Lot. Ludovico'!$B$4
Name ColumnTitle1: 'Prot. TLD - Lot. Vera Cruz'!$B$4
Name ColumnTitle1: 'Prot. TLD - Reserva do Lago'!$B$4
Name ColumnTitle1: 'Prot. TLD - Sede Hélio'!$B$4
Name ColumnTitle1: 'Prot. TLD - Solar de Verona'!$B$4
Name ColumnTitle1: 'Prot. TLD - Sperafico'!$B$4
Name ColumnTitle1: 'Prot. TLD - Villa Bella I'!$B$4
Name ColumnTitle1: 'Prot. TLD - Ducale'!$B$4
Name ColumnTitle2: Tabela_de_categorias_e_funcionários[[#Headers],[Aprovações]]
Name ColumnTitle2: Tabela_de_categorias_e_funcionários[[#Headers],[Aprovações]]
Name ColumnTitle2: Tabela_de_categorias_e_funcionários[[#Headers],[Aprovações]]
Name ColumnTitle2: Tabela_de_categorias_e_funcionários[[#Headers],[Aprovações]]
Name ColumnTitle2: Tabela_de_categorias_e_funcionários[[#Headers],[Aprovações]]
Name ColumnTitle2: Tabela_de_categorias_e_funcionários[[#Headers],[Aprovações]]
Name ColumnTitle2: Tabela_de_categorias_e_funcionários[[#Headers],[Aprovações]]
Name ColumnTitle2: Tabela_de_categorias_e_funcionários[[#Headers],[Aprovações]]
Name ColumnTitle2: Tabela_de_categorias_e_funcionários[[#Headers],[Aprovações]]
Name ColumnTitle2: Tabela_de_categorias_e_funcionários[[#Headers],[Aprovações]]
Name ColumnTitle2: Tabela_de_categorias_e_funcionários[[#Headers],[Aprovações]]
Name ColumnTitle2: Tabela_de_categorias_e_funcionários[[#Headers],[Aprovações]]
Name ColumnTitle2: Tabela_de_categorias_e_funcionários[[#Headers],[Aprovações]]
Name ColumnTitle2: Tabela_de_categorias_e_funcionários[[#Headers],[Aprovações]]
Name ColumnTitle2: Tabela_de_categorias_e_funcionários[[#Headers],[Aprovações]]
Name Funcionário_Lista: Configuração!$C$5:$C$11
Name ll: Tabela_de_categorias_e_funcionários[[#Headers],[Aprovações]]
Name ll: Tabela_de_categorias_e_funcionários[[#Headers],[Aprovações]]
Name SedeHélio: Tabela_de_categorias_e_funcionários[[#Headers],[Aprovações]]
Name SedeHélio: Tabela_de_categorias_e_funcionários[[#Headers],[Aprovações]]
Name SedeHélio: Tabela_de_categorias_e_funcionários[[#Headers],[Aprovações]]
Name SedeHélio: Tabela_de_categorias_e_funcionários[[#Headers],[Aprovações]]
Name SedeHélio: Tabela_de_categorias_e_funcionários[[#Headers],[Aprovações]]
Name SedeHélio: Tabela_de_categorias_e_funcionários[[#Headers],[Aprovações]]
Name SedeHélio: Tabela_de_categorias_e_funcionários[[#Headers],[Aprovações]]
Name SedeHélio: Tabela_de_categorias_e_funcionários[[#Headers],[Aprovações]]
Name Sinalizador_Porcentagem: 'Prot. CVEL - Altona'!$D$2
Name Sinalizador_Porcentagem: 'Prot. CVEL - Bella Citta'!$D$2
Name Sinalizador_Porcentagem: 'Prot. CVEL - Bresolin'!$D$2
Name Sinalizador_Porcentagem: 'Prot. TLD - 13 de Abril'!$D$2
Name Sinalizador_Porcentagem: 'Prot. TLD - Biopark'!$D$2
Name Sinalizador_Porcentagem: 'Prot. TLD - Carmel'!$D$2

Sheet Configuração
B1: Configuração
B4: Aprovações | C4: Nome do Funcionário | D4: Link
B5: Prefeitura Toledo | C5: Lavinia | D5: https://equiplano.toledo.pr.gov.br:7443/contribuinte/#/stpProcessos/pesquisa
B6: Cartório Reg. Imóveis | C6: Lavinia | D6: https://www.cartoriospr.com.br/eandamento/index.php?token=
B7: IAT | C7: Renan | D7: https://www.iat.pr.gov.br/protocolo/info
B8: ANAC | C8: Michael | D8: https://sei.anac.gov.br/sei/controlador_externo.php?acao=usuario_externo_logar&id_orgao_acesso_externo=0
B9: Sanepar | C9: Cristian | D9: https://auth-cs.identidadedigital.pr.gov.br/centralautenticacao/login.html?response_type=code&client_id=9188905e74c28e489b44e954ec0b9bca&redirect_uri=https%3A%2F%2Fwww.eprotocolo.pr.gov.br%2Fspiweb&scope=null&state=1779132779562&urlCert=https://certauth-cs.identidadedigital.pr.gov.br&dnsCidadao=https://cidadao-cs.identidadedigital.pr.gov.br/centralcidadao&loginPadrao=btnCentral&labelCentral=CPF&modulosDeAutenticacao=btnCertificado,btnCpf,btnSanepar,btnCentral&urlLogo=https%3A%2F%2Fwww.eprotocolo.pr.gov.br%2Fspiweb%2Fimages%2Flogo_eprotocolo.png&acesso=2096&tokenFormat=jwt&exibirLinkAutoCadastro=true&exibirLinkRecuperarSenha=true&exibirLinkAutoCadastroCertificado=false&exibirAviso=true&captcha=false
B10: Copel | C10: Renan | D10: https://www.copel.com/site/copel-distribuicao/acompanhamento-de-solicitacoes/?utm_source=home-page&utm_medium=consulta-protocolo&utm_campaign=servicos
B11: IPHAN | C11: Renan | D11: https://saip.iphan.gov.br/
B12: Corpo de Bombeiros | C12: Cristian | D12: https://auth-cs.identidadedigital.pr.gov.br/centralautenticacao/login.html?response_type=code&client_id=9188905e74c28e489b44e954ec0b9bca&redirect_uri=https%3A%2F%2Fwww.eprotocolo.pr.gov.br%2Fspiweb&scope=null&state=1779132779562&urlCert=https://certauth-cs.identidadedigital.pr.gov.br&dnsCidadao=https://cidadao-cs.identidadedigital.pr.gov.br/centralcidadao&loginPadrao=btnCentral&labelCentral=CPF&modulosDeAutenticacao=btnCertificado,btnCpf,btnSanepar,btnCentral&urlLogo=https%3A%2F%2Fwww.eprotocolo.pr.gov.br%2Fspiweb%2Fimages%2Flogo_eprotocolo.png&acesso=2096&tokenFormat=jwt&exibirLinkAutoCadastro=true&exibirLinkRecuperarSenha=true&exibirLinkAutoCadastroCertificado=false&exibirAviso=true&captcha=false
B13: Prefeitura de Cascavel | C13: Michael | D13: https://prefa.cascavel.pr.gov.br/autoatendimento/servicos/consulta-de-processo-digital

Sheet Prot. TLD - Horizont
B1: Controlador De Protocolos Residencial Horizont - Toledo
D2: Sinalizador de Porcentagem Acima/Abaixo:
A4: STATUS | B4: Projeto + Protocolo | C4: Atividade | D4: Aprovações | E4: Atribuída a | F4: Estimado Início | G4: Estimado Término | H4: Duração Estimada (em dias) | I4: Real Início | J4: Real Término | K4: Sinalizador para duração real acima/abaixo (em dias)S | L4: Duração Real (em dias) | M4: Anotações | N4: Situação
A5: APRO | B5: Horizont - 50027/2023 | C5: Alvará de Construção | D5: Prefeitura Toledo | E5: Michael | F5: 45224 | G5: 45338 | H5: =IF(COUNTA('Prot. TLD - Horizont'!$F5,'Prot. TLD - Horizont'!$G5)<>2,"",DAYS360('Prot. TLD - Horizont'!$F5,'Prot. TLD - Horizont'!$G5,FALSE)) -> 111 | I5: 45224 | J5: 45366 | K5: =IFERROR(IF(ControladorDeProjetos5[[#This Row],[Duração Real (em dias)]]=0,"",IF(ABS((ControladorDeProjetos5[[#This Row],[Duração Real (em dias)]]-ControladorDeProjetos5[[#This Row],[Duração Estimada (em dias)]])/ControladorDeProjetos5[[#This Row],[Duração Estimada (em dias)]])>Sinalizador_Porcentagem,1,0)),"") -> 1 | L5: =IF(COUNTA('Prot. TLD - Horizont'!$I5,'Prot. TLD - Horizont'!$J5)<>2,"",DAYS360('Prot. TLD - Horizont'!$I5,'Prot. TLD - Horizont'!$J5,FALSE)) -> 140 | M5: Correções Encaminhada CLOS> | N5: Retirado / Arquitetos
A6: APRO | B6: Horizont - 49428/2023 | C6: Desmembramento | D6: Prefeitura Toledo | E6: Michael | F6: 45215 | G6: 45280 | H6: =IF(COUNTA('Prot. TLD - Horizont'!$F6,'Prot. TLD - Horizont'!$G6)<>2,"",DAYS360('Prot. TLD - Horizont'!$F6,'Prot. TLD - Horizont'!$G6,FALSE)) -> 64 | I6: 45215 | J6: 45280 | K6: =IFERROR(IF(ControladorDeProjetos5[[#This Row],[Duração Real (em dias)]]=0,"",IF(ABS((ControladorDeProjetos5[[#This Row],[Duração Real (em dias)]]-ControladorDeProjetos5[[#This Row],[Duração Estimada (em dias)]])/ControladorDeProjetos5[[#This Row],[Duração Estimada (em dias)]])>Sinalizador_Porcentagem,1,0)),"") -> 0 | L6: =IF(COUNTA('Prot. TLD - Horizont'!$I6,'Prot. TLD - Horizont'!$J6)<>2,"",DAYS360('Prot. TLD - Horizont'!$I6,'Prot. TLD - Horizont'!$J6,FALSE)) -> 64 | M6: 1ºAprovação | N6: Protocolo Finalizado
A7: APRO | B7: Horizont - 1923/2024 | C7: Recarimbo Desmembramento | D7: Prefeitura Toledo | E7: Michael | F7: 45307 | G7: 45314 | H7: =IF(COUNTA('Prot. TLD - Horizont'!$F7,'Prot. TLD - Horizont'!$G7)<>2,"",DAYS360('Prot. TLD - Horizont'!$F7,'Prot. TLD - Horizont'!$G7,FALSE)) -> 7 | I7: 45307 | J7: 45314 | K7: =IFERROR(IF(ControladorDeProjetos5[[#This Row],[Duração Real (em dias)]]=0,"",IF(ABS((ControladorDeProjetos5[[#This Row],[Duração Real (em dias)]]-ControladorDeProjetos5[[#This Row],[Duração Estimada (em dias)]])/ControladorDeProjetos5[[#This Row],[Duração Estimada (em dias)]])>Sinalizador_Porcentagem,1,0)),"") -> 0 | L7: =IF(COUNTA('Prot. TLD - Horizont'!$I7,'Prot. TLD - Horizont'!$J7)<>2,"",DAYS360('Prot. TLD - Horizont'!$I7,'Prot. TLD - Horizont'!$J7,FALSE)) -> 7 | M7: Tainara irá Analisar | N7: Análise Prefeitura
A8: APRO | B8: Horizont - 328.011 06/12/2023 Alteração de Protocolo 329.317 | C8: Desmembramento | D8: Cartório Reg. Imóveis | E8: Michael | F8: 45266 | G8: 44983 | H8: =IF(COUNTA('Prot. TLD - Horizont'!$F8,'Prot. TLD - Horizont'!$G8)<>2,"",DAYS360('Prot. TLD - Horizont'!$F8,'Prot. TLD - Horizont'!$G8,FALSE)) -> -280 | I8: 45266 | J8: 45350 | K8: =IFERROR(IF(ControladorDeProjetos5[[#This Row],[Duração Real (em dias)]]=0,"",IF(ABS((ControladorDeProjetos5[[#This Row],[Duração Real (em dias)]]-ControladorDeProjetos5[[#This Row],[Duração Estimada (em dias)]])/ControladorDeProjetos5[[#This Row],[Duração Estimada (em dias)]])>Sinalizador_Porcentagem,1,0)),"") -> 1 | L8: =IF(COUNTA('Prot. TLD - Horizont'!$I8,'Prot. TLD - Horizont'!$J8)<>2,"",DAYS360('Prot. TLD - Horizont'!$I8,'Prot. TLD - Horizont'!$J8,FALSE)) -> 82 | M8: Aguardando Análise Cartório | N8: Aguardando
A9: APRO | B9: Horizont - IAT 21.594.976-1 | C9: Autorização Ambiental Desmembramento | D9: IAT | E9: Michael | F9: 45308 | G9: 45317 | H9: =IF(COUNTA('Prot. TLD - Horizont'!$F9,'Prot. TLD - Horizont'!$G9)<>2,"",DAYS360('Prot. TLD - Horizont'!$F9,'Prot. TLD - Horizont'!$G9,FALSE)) -> 9 | I9: 45309 | J9: 45320 | K9: =IFERROR(IF(ControladorDeProjetos5[[#This Row],[Duração Real (em dias)]]=0,"",IF(ABS((ControladorDeProjetos5[[#This Row],[Duração Real (em dias)]]-ControladorDeProjetos5[[#This Row],[Duração Estimada (em dias)]])/ControladorDeProjetos5[[#This Row],[Duração Estimada (em dias)]])>Sinalizador_Porcentagem,1,0)),"") -> 1 | L9: =IF(COUNTA('Prot. TLD - Horizont'!$I9,'Prot. TLD - Horizont'!$J9)<>2,"",DAYS360('Prot. TLD - Horizont'!$I9,'Prot. TLD - Horizont'!$J9,FALSE)) -> 11 | M9: Protocolo Aberto | N9: Em Análise Protocolo Criado em 18/01/2024
A10: APRO | B10: Horizont - 21.656.886-9 2024 | C10: LAS - Licenciamento Ambiental Simplificado | D10: IAT | E10: Michael | F10: 45322 | G10: 45366 | H10: =IF(COUNTA('Prot. TLD - Horizont'!$F10,'Prot. TLD - Horizont'!$G10)<>2,"",DAYS360('Prot. TLD - Horizont'!$F10,'Prot. TLD - Horizont'!$G10,FALSE)) -> 45 | I10: 45322 | J10: 45372 | K10: =IFERROR(IF(ControladorDeProjetos5[[#This Row],[Duração Real (em dias)]]=0,"",IF(ABS((ControladorDeProjetos5[[#This Row],[Duração Real (em dias)]]-ControladorDeProjetos5[[#This Row],[Duração Estimada (em dias)]])/ControladorDeProjetos5[[#This Row],[Duração Estimada (em dias)]])>Sinalizador_Porcentagem,1,0)),"") -> 1 | L10: =IF(COUNTA('Prot. TLD - Horizont'!$I10,'Prot. TLD - Horizont'!$J10)<>2,"",DAYS360('Prot. TLD - Horizont'!$I10,'Prot. TLD - Horizont'!$J10,FALSE)) -> 51 | M10: Arquivos Entregues para Análise | N10: Protocolo Aberto
A11: CANC | B11: Horizont - 01450.000692/2024-36 | C11: Anuência IPHAN | D11: IPHAN | E11: Michael | F11: 45317 | G11: 45348 | H11: =IF(COUNTA('Prot. TLD - Horizont'!$F11,'Prot. TLD - Horizont'!$G11)<>2,"",DAYS360('Prot. TLD - Horizont'!$F11,'Prot. TLD - Horizont'!$G11,FALSE)) -> 30 | I11: 45317 | K11: =IFERROR(IF(ControladorDeProjetos5[[#This Row],[Duração Real (em dias)]]=0,"",IF(ABS((ControladorDeProjetos5[[#This Row],[Duração Real (em dias)]]-ControladorDeProjetos5[[#This Row],[Duração Estimada (em dias)]])/ControladorDeProjetos5[[#This Row],[Duração Estimada (em dias)]])>Sinalizador_Porcentagem,1,0)),"") | L11: =IF(COUNTA('Prot. TLD - Horizont'!$I11,'Prot. TLD - Horizont'!$J11)<>2,"",DAYS360('Prot. TLD - Horizont'!$I11,'Prot. TLD - Horizont'!$J11,FALSE)) | M11: Anuência IPHAN Qunato a Implantação do Empreendimento | N11: Protocolo Aberto
A12: CANC | B12: Horizont - 2.2.01.24.0001668600-47 | C12: Aprovação PCIP | D12: Corpo de Bombeiros | E12: Michael | F12: 45321 | G12: 45350 | H12: =IF(COUNTA('Prot. TLD - Horizont'!$F12,'Prot. TLD - Horizont'!$G12)<>2,"",DAYS360('Prot. TLD - Horizont'!$F12,'Prot. TLD - Horizont'!$G12,FALSE)) -> 28 | I12: 45321 | K12: =IFERROR(IF(ControladorDeProjetos5[[#This Row],[Duração Real (em dias)]]=0,"",IF(ABS((ControladorDeProjetos5[[#This Row],[Duração Real (em dias)]]-ControladorDeProjetos5[[#This Row],[Duração Estimada (em dias)]])/ControladorDeProjetos5[[#This Row],[Duração Estimada (em dias)]])>Sinalizador_Porcentagem,1,0)),"") | L12: =IF(COUNTA('Prot. TLD - Horizont'!$I12,'Prot. TLD - Horizont'!$J12)<>2,"",DAYS360('Prot. TLD - Horizont'!$I12,'Prot. TLD - Horizont'!$J12,FALSE)) | M12: Protocolo Aberto Aprovação de Projetos | N12: 1º Análise Realizada Projetista Realizando Alterações
A13: APRO | B13: Horizont - 2597 / 2024 | C13: Notificação Laudo Cautelar | D13: Cartório | E13: Michael | F13: 45324 | G13: 45353 | H13: =IF(COUNTA('Prot. TLD - Horizont'!$F13,'Prot. TLD - Horizont'!$G13)<>2,"",DAYS360('Prot. TLD - Horizont'!$F13,'Prot. TLD - Horizont'!$G13,FALSE)) -> 30 | I13: 45324 | J13: 45351 | K13: =IFERROR(IF(ControladorDeProjetos5[[#This Row],[Duração Real (em dias)]]=0,"",IF(ABS((ControladorDeProjetos5[[#This Row],[Duração Real (em dias)]]-ControladorDeProjetos5[[#This Row],[Duração Estimada (em dias)]])/ControladorDeProjetos5[[#This Row],[Duração Estimada (em dias)]])>Sinalizador_Porcentagem,1,0)),"") -> 1 | L13: =IF(COUNTA('Prot. TLD - Horizont'!$I13,'Prot. TLD - Horizont'!$J13)<>2,"",DAYS360('Prot. TLD - Horizont'!$I13,'Prot. TLD - Horizont'!$J13,FALSE)) -> 27 | M13: Protocolado em Cartório | N13: Protocolo Aberto
A14: APRO | B14: Horizont - 2598 / 2024 | C14: Notificação Laudo Cautelar | D14: Cartório | E14: Michael | F14: 45324 | G14: 45353 | H14: =IF(COUNTA('Prot. TLD - Horizont'!$F14,'Prot. TLD - Horizont'!$G14)<>2,"",DAYS360('Prot. TLD - Horizont'!$F14,'Prot. TLD - Horizont'!$G14,FALSE)) -> 30 | I14: 45324 | J14: 45351 | K14: =IFERROR(IF(ControladorDeProjetos5[[#This Row],[Duração Real (em dias)]]=0,"",IF(ABS((ControladorDeProjetos5[[#This Row],[Duração Real (em dias)]]-ControladorDeProjetos5[[#This Row],[Duração Estimada (em dias)]])/ControladorDeProjetos5[[#This Row],[Duração Estimada (em dias)]])>Sinalizador_Porcentagem,1,0)),"") -> 1 | L14: =IF(COUNTA('Prot. TLD - Horizont'!$I14,'Prot. TLD - Horizont'!$J14)<>2,"",DAYS360('Prot. TLD - Horizont'!$I14,'Prot. TLD - Horizont'!$J14,FALSE)) -> 27 | M14: Protocolado em Cartório | N14: Protocolo Aberto
A15: APRO | B15: Horizont - 2599 / 2024 | C15: Notificação Laudo Cautelar | D15: Cartório | E15: Michael | F15: 45324 | G15: 45353 | H15: =IF(COUNTA('Prot. TLD - Horizont'!$F15,'Prot. TLD - Horizont'!$G15)<>2,"",DAYS360('Prot. TLD - Horizont'!$F15,'Prot. TLD - Horizont'!$G15,FALSE)) -> 30 | I15: 45324 | J15: 45351 | K15: =IFERROR(IF(ControladorDeProjetos5[[#This Row],[Duração Real (em dias)]]=0,"",IF(ABS((ControladorDeProjetos5[[#This Row],[Duração Real (em dias)]]-ControladorDeProjetos5[[#This Row],[Duração Estimada (em dias)]])/ControladorDeProjetos5[[#This Row],[Duração Estimada (em dias)]])>Sinalizador_Porcentagem,1,0)),"") -> 1 | L15: =IF(COUNTA('Prot. TLD - Horizont'!$I15,'Prot. TLD - Horizont'!$J15)<>2,"",DAYS360('Prot. TLD - Horizont'!$I15,'Prot. TLD - Horizont'!$J15,FALSE)) -> 27 | M15: Protocolado em Cartório | N15: Protocolo Aberto
A16: APRO | B16: Horizont - 2600 / 2024 | C16: Notificação Laudo Cautelar | D16: Cartório | E16: Michael | F16: 45324 | G16: 45353 | H16: =IF(COUNTA('Prot. TLD - Horizont'!$F16,'Prot. TLD - Horizont'!$G16)<>2,"",DAYS360('Prot. TLD - Horizont'!$F16,'Prot. TLD - Horizont'!$G16,FALSE)) -> 30 | I16: 45324 | J16: 45351 | K16: =IFERROR(IF(ControladorDeProjetos5[[#This Row],[Duração Real (em dias)]]=0,"",IF(ABS((ControladorDeProjetos5[[#This Row],[Duração Real (em dias)]]-ControladorDeProjetos5[[#This Row],[Duração Estimada (em dias)]])/ControladorDeProjetos5[[#This Row],[Duração Estimada (em dias)]])>Sinalizador_Porcentagem,1,0)),"") -> 1 | L16: =IF(COUNTA('Prot. TLD - Horizont'!$I16,'Prot. TLD - Horizont'!$J16)<>2,"",DAYS360('Prot. TLD - Horizont'!$I16,'Prot. TLD - Horizont'!$J16,FALSE)) -> 27 | M16: Protocolado em Cartório | N16: Protocolo Aberto
A17: CANC | B17: Horizont - 20245957717392 | C17: Ligação Provisória Copel | D17: Copel | E17: Michael | F17: 45355 | G17: 45363 | H17: =IF(COUNTA('Prot. TLD - Horizont'!$F17,'Prot. TLD - Horizont'!$G17)<>2,"",DAYS360('Prot. TLD - Horizont'!$F17,'Prot. TLD - Horizont'!$G17,FALSE)) -> 8 | I17: 45355 | J17: 45369 | K17: =IFERROR(IF(ControladorDeProjetos5[[#This Row],[Duração Real (em dias)]]=0,"",IF(ABS((ControladorDeProjetos5[[#This Row],[Duração Real (em dias)]]-ControladorDeProjetos5[[#This Row],[Duração Estimada (em dias)]])/ControladorDeProjetos5[[#This Row],[Duração Estimada (em dias)]])>Sinalizador_Porcentagem,1,0)),"") -> 1 | L17: =IF(COUNTA('Prot. TLD - Horizont'!$I17,'Prot. TLD - Horizont'!$J17)<>2,"",DAYS360('Prot. TLD - Horizont'!$I17,'Prot. TLD - Horizont'!$J17,FALSE)) -> 14 | M17: Protocolado em Copel | N17: Protocolo Aberto
A18: APRO | B18: Horizont - 330.571 | C18: Incoporação Imobiliária | D18: Cartório Reg. Imóveis | E18: Michael | F18: 45366 | G18: 45379 | H18: =IF(COUNTA('Prot. TLD - Horizont'!$F18,'Prot. TLD - Horizont'!$G18)<>2,"",DAYS360('Prot. TLD - Horizont'!$F18,'Prot. TLD - Horizont'!$G18,FALSE)) -> 13 | I18: 45366 | J18: 45411 | K18: =IFERROR(IF(ControladorDeProjetos5[[#This Row],[Duração Real (em dias)]]=0,"",IF(ABS((ControladorDeProjetos5[[#This Row],[Duração Real (em dias)]]-ControladorDeProjetos5[[#This Row],[Duração Estimada (em dias)]])/ControladorDeProjetos5[[#This Row],[Duração Estimada (em dias)]])>Sinalizador_Porcentagem,1,0)),"") -> 1 | L18: =IF(COUNTA('Prot. TLD - Horizont'!$I18,'Prot. TLD - Horizont'!$J18)<>2,"",DAYS360('Prot. TLD - Horizont'!$I18,'Prot. TLD - Horizont'!$J18,FALSE)) -> 44 | M18: Abertura de Processo | N18: 29/04/2024 - Finalizado
A19: APRO | B19: Horizont - 20246044579234 | C19: Ligação Provisória Copel | D19: Copel | E19: Michael | F19: 45369 | G19: 45376 | H19: =IF(COUNTA('Prot. TLD - Horizont'!$F19,'Prot. TLD - Horizont'!$G19)<>2,"",DAYS360('Prot. TLD - Horizont'!$F19,'Prot. TLD - Horizont'!$G19,FALSE)) -> 7 | I19: 45369 | J19: 45398 | K19: =IFERROR(IF(ControladorDeProjetos5[[#This Row],[Duração Real (em dias)]]=0,"",IF(ABS((ControladorDeProjetos5[[#This Row],[Duração Real (em dias)]]-ControladorDeProjetos5[[#This Row],[Duração Estimada (em dias)]])/ControladorDeProjetos5[[#This Row],[Duração Estimada (em dias)]])>Sinalizador_Porcentagem,1,0)),"") -> 1 | L19: =IF(COUNTA('Prot. TLD - Horizont'!$I19,'Prot. TLD - Horizont'!$J19)<>2,"",DAYS360('Prot. TLD - Horizont'!$I19,'Prot. TLD - Horizont'!$J19,FALSE)) -> 28 | M19: Solicitação Liagção de 80A | N19: 16/04/2024 - Finalizado
A20: ANÁL | B20: 20259368532011 | C20: Ampliação de Carga | D20: Copel | E20: Cristian | F20: 45799 | G20: 45834 | H20: =IF(COUNTA('Prot. TLD - Horizont'!$F20,'Prot. TLD - Horizont'!$G20)<>2,"",DAYS360('Prot. TLD - Horizont'!$F20,'Prot. TLD - Horizont'!$G20,FALSE)) -> 34 | I20: 45799 | K20: =IFERROR(IF(ControladorDeProjetos5[[#This Row],[Duração Real (em dias)]]=0,"",IF(ABS((ControladorDeProjetos5[[#This Row],[Duração Real (em dias)]]-ControladorDeProjetos5[[#This Row],[Duração Estimada (em dias)]])/ControladorDeProjetos5[[#This Row],[Duração Estimada (em dias)]])>Sinalizador_Porcentagem,1,0)),"") | L20: =IF(COUNTA('Prot. TLD - Horizont'!$I20,'Prot. TLD - Horizont'!$J20)<>2,"",DAYS360('Prot. TLD - Horizont'!$I20,'Prot. TLD - Horizont'!$J20,FALSE)) | M20: aprovação de orçamento pelo cliente
A21: ANÁL | B21: Horizont II - 244444482 | C21: Protocolo SANEPAR | D21: Sanepar | E21: Cristian | F21: 45875 | G21: 45917 | H21: =IF(COUNTA('Prot. TLD - Horizont'!$F21,'Prot. TLD - Horizont'!$G21)<>2,"",DAYS360('Prot. TLD - Horizont'!$F21,'Prot. TLD - Horizont'!$G21,FALSE)) -> 41 | I21: 45875 | K21: =IFERROR(IF(ControladorDeProjetos5[[#This Row],[Duração Real (em dias)]]=0,"",IF(ABS((ControladorDeProjetos5[[#This Row],[Duração Real (em dias)]]-ControladorDeProjetos5[[#This Row],[Duração Estimada (em dias)]])/ControladorDeProjetos5[[#This Row],[Duração Estimada (em dias)]])>Sinalizador_Porcentagem,1,0)),"") | L21: =IF(COUNTA('Prot. TLD - Horizont'!$I21,'Prot. TLD - Horizont'!$J21)<>2,"",DAYS360('Prot. TLD - Horizont'!$I21,'Prot. TLD - Horizont'!$J21,FALSE)) | M21: Aprovação de projeto para ligação da servidão | N21: Protocolo aberto
A22: CANC | B22: 41779 / 2025 | C22: Liberação para reforma de calçada e rua | D22: Prefeitura Toledo | E22: Eduarda | F22: 45897 | G22: =F22+15 -> 45912 | H22: =IF(COUNTA('Prot. TLD - Horizont'!$F22,'Prot. TLD - Horizont'!$G22)<>2,"",DAYS360('Prot. TLD - Horizont'!$F22,'Prot. TLD - Horizont'!$G22,FALSE)) -> 14 | I22: 45897 | K22: =IFERROR(IF(ControladorDeProjetos5[[#This Row],[Duração Real (em dias)]]=0,"",IF(ABS((ControladorDeProjetos5[[#This Row],[Duração Real (em dias)]]-ControladorDeProjetos5[[#This Row],[Duração Estimada (em dias)]])/ControladorDeProjetos5[[#This Row],[Duração Estimada (em dias)]])>Sinalizador_Porcentagem,1,0)),"") | L22: =IF(COUNTA('Prot. TLD - Horizont'!$I22,'Prot. TLD - Horizont'!$J22)<>2,"",DAYS360('Prot. TLD - Horizont'!$I22,'Prot. TLD - Horizont'!$J22,FALSE)) | N22: Protocolo Aberto
A23: ANÁL | B23: Sanepar - 20250827115509211 | C23: Ligação definitiva | D23: Sanepar | E23: Cristian | F23: 45896 | G23: =F23+15 -> 45911 | H23: =IF(COUNTA('Prot. TLD - Horizont'!$F23,'Prot. TLD - Horizont'!$G23)<>2,"",DAYS360('Prot. TLD - Horizont'!$F23,'Prot. TLD - Horizont'!$G23,FALSE)) -> 14 | I23: 45896 | K23: =IFERROR(IF(ControladorDeProjetos5[[#This Row],[Duração Real (em dias)]]=0,"",IF(ABS((ControladorDeProjetos5[[#This Row],[Duração Real (em dias)]]-ControladorDeProjetos5[[#This Row],[Duração Estimada (em dias)]])/ControladorDeProjetos5[[#This Row],[Duração Estimada (em dias)]])>Sinalizador_Porcentagem,1,0)),"") | L23: =IF(COUNTA('Prot. TLD - Horizont'!$I23,'Prot. TLD - Horizont'!$J23)<>2,"",DAYS360('Prot. TLD - Horizont'!$I23,'Prot. TLD - Horizont'!$J23,FALSE)) | N23: Protocolo aberto
A24: APRO | B24: Horizont - 50917 / 2025 | C24: Aprovação de drenagem | D24: Prefeitura Toledo | E24: Eduarda | F24: 45947 | G24: 45978 | H24: =G24-F24 -> 31 | I24: 45947 | J24: 46035 | K24: =IFERROR(IF(ControladorDeProjetos5[[#This Row],[Duração Real (em dias)]]=0,"",IF(ABS((ControladorDeProjetos5[[#This Row],[Duração Real (em dias)]]-ControladorDeProjetos5[[#This Row],[Duração Estimada (em dias)]])/ControladorDeProjetos5[[#This Row],[Duração Estimada (em dias)]])>Sinalizador_Porcentagem,1,0)),"") | L24: =J24-I24 -> 88 | M24: Aprovação de projeto para a ligação de drenagem do empreendimento | N24: Protocolo aberto

Sheet Prot. TLD - Ducale
B1: Controlador De Protocolos Residencial Ducale - Toledo
D2: Sinalizador de Porcentagem Acima/Abaixo:
A4: STATUS | B4: Projeto + Protocolo | C4: Atividade | D4: Aprovações | E4: Atribuída a | F4: Estimado Início | G4: Estimado Término | H4: Duração Estimada (em dias) | I4: Real Início | J4: Real Término | K4: Sinalizador para duração real acima/abaixo (em dias)S | L4: Duração Real (em dias) | M4: Anotações | N4: Situação
A5: APRO | B5: Ducale - 50900/2023 | C5: Renovação Alvará | D5: Prefeitura Toledo | E5: Michael | F5: 45223 | G5: 45321 | H5: =IF(COUNTA('Prot. TLD - Ducale'!$F5,'Prot. TLD - Ducale'!$G5)<>2,"",DAYS360('Prot. TLD - Ducale'!$F5,'Prot. TLD - Ducale'!$G5,FALSE)) -> 96 | I5: 45223 | J5: 45320 | K5: =IFERROR(IF(ControladorDeProjetos[[#This Row],[Duração Real (em dias)]]=0,"",IF(ABS((ControladorDeProjetos[[#This Row],[Duração Real (em dias)]]-ControladorDeProjetos[[#This Row],[Duração Estimada (em dias)]])/ControladorDeProjetos[[#This Row],[Duração Estimada (em dias)]])>Sinalizador_Porcentagem,1,0)),"") -> 1 | L5: =IF(COUNTA('Prot. TLD - Ducale'!$I5,'Prot. TLD - Ducale'!$J5)<>2,"",DAYS360('Prot. TLD - Ducale'!$I5,'Prot. TLD - Ducale'!$J5,FALSE)) -> 95 | M5: Pagamento da Taxa Realizado e Encaminhado ao Setor Responsável | N5: Análise Prefeitura
A6: CANC | B6: Duucale - 20240119.1537.02016 | C6: Solicitação Ponto de Esgoto | D6: Sanepar | E6: Michael | F6: 45310 | G6: 45342 | H6: =IF(COUNTA('Prot. TLD - Ducale'!$F6,'Prot. TLD - Ducale'!$G6)<>2,"",DAYS360('Prot. TLD - Ducale'!$F6,'Prot. TLD - Ducale'!$G6,FALSE)) -> 31 | I6: 45310 | K6: =IFERROR(IF(ControladorDeProjetos[[#This Row],[Duração Real (em dias)]]=0,"",IF(ABS((ControladorDeProjetos[[#This Row],[Duração Real (em dias)]]-ControladorDeProjetos[[#This Row],[Duração Estimada (em dias)]])/ControladorDeProjetos[[#This Row],[Duração Estimada (em dias)]])>Sinalizador_Porcentagem,1,0)),"") | L6: =IF(COUNTA('Prot. TLD - Ducale'!$I6,'Prot. TLD - Ducale'!$J6)<>2,"",DAYS360('Prot. TLD - Ducale'!$I6,'Prot. TLD - Ducale'!$J6,FALSE)) | M6: Aguardando Prazo de 30 Dias / Solicitação de execução de mais um ponto de esgoto, conforme projeto aprovado | N6: ProtocoloAberto
A7: CANC | B7: Ducale - 20245757138534 | C7: Atualização Valor Padrão de Entrada | D7: Copel | E7: Michael | F7: 45313 | G7: 45344 | H7: =IF(COUNTA('Prot. TLD - Ducale'!$F7,'Prot. TLD - Ducale'!$G7)<>2,"",DAYS360('Prot. TLD - Ducale'!$F7,'Prot. TLD - Ducale'!$G7,FALSE)) -> 30 | I7: 45313 | K7: =IFERROR(IF(ControladorDeProjetos[[#This Row],[Duração Real (em dias)]]=0,"",IF(ABS((ControladorDeProjetos[[#This Row],[Duração Real (em dias)]]-ControladorDeProjetos[[#This Row],[Duração Estimada (em dias)]])/ControladorDeProjetos[[#This Row],[Duração Estimada (em dias)]])>Sinalizador_Porcentagem,1,0)),"") | L7: =IF(COUNTA('Prot. TLD - Ducale'!$I7,'Prot. TLD - Ducale'!$J7)<>2,"",DAYS360('Prot. TLD - Ducale'!$I7,'Prot. TLD - Ducale'!$J7,FALSE)) | M7: Ataulização de Valor Prolongamento de Rede | N7: Protocolo Aberto
A8: APRO | B8: 2.2.01.25.0001529159-23 | C8: Aprovação corpo de bombeiros - PR | D8: Corpo de Bombeiros | E8: Suellen / Isabelly | F8: 45730 | G8: =ControladorDeProjetos[[#This Row],[Estimado Início]]+60 -> 45790 | H8: =IF(COUNTA('Prot. TLD - Ducale'!$F8,'Prot. TLD - Ducale'!$G8)<>2,"",DAYS360('Prot. TLD - Ducale'!$F8,'Prot. TLD - Ducale'!$G8,FALSE)) -> 59 | I8: 45730 | K8: =IFERROR(IF(ControladorDeProjetos[[#This Row],[Duração Real (em dias)]]=0,"",IF(ABS((ControladorDeProjetos[[#This Row],[Duração Real (em dias)]]-ControladorDeProjetos[[#This Row],[Duração Estimada (em dias)]])/ControladorDeProjetos[[#This Row],[Duração Estimada (em dias)]])>Sinalizador_Porcentagem,1,0)),"") | L8: =IF(COUNTA('Prot. TLD - Ducale'!$I8,'Prot. TLD - Ducale'!$J8)<>2,"",DAYS360('Prot. TLD - Ducale'!$I8,'Prot. TLD - Ducale'!$J8,FALSE)) | M8: Aqua engenharia esta fazendo a aprovação para nós | N8: Protocolo Aberto
A9: ANÁL | B9: 35432 | C9: Ligação definitiva ducale | D9: Copel | E9: Cristian | F9: 45887 | G9: =F9+30 -> 45917 | H9: =IF(COUNTA('Prot. TLD - Ducale'!$F9,'Prot. TLD - Ducale'!$G9)<>2,"",DAYS360('Prot. TLD - Ducale'!$F9,'Prot. TLD - Ducale'!$G9,FALSE)) -> 29 | I9: 45887 | K9: =IFERROR(IF(ControladorDeProjetos[[#This Row],[Duração Real (em dias)]]=0,"",IF(ABS((ControladorDeProjetos[[#This Row],[Duração Real (em dias)]]-ControladorDeProjetos[[#This Row],[Duração Estimada (em dias)]])/ControladorDeProjetos[[#This Row],[Duração Estimada (em dias)]])>Sinalizador_Porcentagem,1,0)),"") | L9: =IF(COUNTA('Prot. TLD - Ducale'!$I9,'Prot. TLD - Ducale'!$J9)<>2,"",DAYS360('Prot. TLD - Ducale'!$I9,'Prot. TLD - Ducale'!$J9,FALSE)) | N9: Protocolo Aberto

Sheet Prot. TLD - Villa Bella I
A1: Controlador De Protocolos Villa Bella I - Toledo | E1: CNPJ PRATI: | F1: 35.538.973/0001-63 | G1: CPF RODRIGO | H1: 078.910.009-64
C2: Sinalizador de Porcentagem Acima/Abaixo: | E2: CNPJ VILLA BELLA: | F2: 57.740.735/0001-79
A4: Status | B4: Projeto + Protocolo | C4: Atividade | D4: Aprovações | E4: Atribuída a | F4: Estimado Início | G4: Estimado Término | H4: Duração Estimada (em dias) | I4: Real Início | J4: Real Término | K4: Sinalizador para duração real acima/abaixo (em dias)S | L4: Duração Real (em dias) | M4: Anotações | N4: Situação
A5: APRO | B5: Ceconi - 40136 /2024 | C5: Solicitação a Comissão de Urbanismo - COMURB - Versão 1 - CNPJ: 04047086924 | D5: Prefeitura Toledo | E5: Michael | F5: 45519 | G5: 45550 | H5: =IF(COUNTA('Prot. TLD - Villa Bella I'!$F5,'Prot. TLD - Villa Bella I'!$G5)<>2,"",DAYS360('Prot. TLD - Villa Bella I'!$F5,'Prot. TLD - Villa Bella I'!$G5,FALSE)) -> 30 | I5: 45519 | J5: 45589 | K5: =IFERROR(IF(ControladorDeProjetos38[[#This Row],[Duração Real (em dias)]]=0,"",IF(ABS((ControladorDeProjetos38[[#This Row],[Duração Real (em dias)]]-ControladorDeProjetos38[[#This Row],[Duração Estimada (em dias)]])/ControladorDeProjetos38[[#This Row],[Duração Estimada (em dias)]])>Sinalizador_Porcentagem,1,0)),"") -> 1 | L5: =ControladorDeProjetos38[[#This Row],[Real Término]]-ControladorDeProjetos38[[#This Row],[Real Início]] -> 70 | M5: Aprovado | N5: Concluido
A6: APRO | B6: Ceconi - 48687/2024 | C6: Desmembramento Imóvel Urbano - CNPJ: 36.686.706/0001-04 | D6: Prefeitura Toledo | E6: Michael | F6: 45567 | G6: 45574 | H6: =ControladorDeProjetos38[[#This Row],[Estimado Término]]-ControladorDeProjetos38[[#This Row],[Estimado Início]] -> 7 | I6: 45567 | J6: 45607 | L6: =ControladorDeProjetos38[[#This Row],[Real Término]]-ControladorDeProjetos38[[#This Row],[Real Início]] -> 40 | M6: Aprovado | N6: Concluido
A7: APRO | B7: Ceconi - 52374 / 2024 | C7: Análise Prévia de Projeto - EIV | D7: Prefeitura Toledo | E7: Michael | F7: 45699 | G7: =ControladorDeProjetos38[[#This Row],[Estimado Início]]+30 -> 45729 | H7: =IF(COUNTA('Prot. TLD - Villa Bella I'!$F7,'Prot. TLD - Villa Bella I'!$G7)<>2,"",DAYS360('Prot. TLD - Villa Bella I'!$F7,'Prot. TLD - Villa Bella I'!$G7,FALSE)) -> 32 | I7: 45716 | J7: 45734 | L7: =ControladorDeProjetos38[[#This Row],[Real Término]]-ControladorDeProjetos38[[#This Row],[Real Início]] -> 18 | M7: Aprovado | N7: Concluido
A8: APRO | B8: Ceconi - 52374 / 2024 | C8: Análise Prévia de Projeto - Versão 1 | D8: Prefeitura Toledo | E8: Michael | F8: 45587 | G8: 45618 | H8: =IF(COUNTA('Prot. TLD - Villa Bella I'!$F8,'Prot. TLD - Villa Bella I'!$G8)<>2,"",DAYS360('Prot. TLD - Villa Bella I'!$F8,'Prot. TLD - Villa Bella I'!$G8,FALSE)) -> 30 | I8: 45587 | J8: 45743 | L8: =ControladorDeProjetos38[[#This Row],[Real Término]]-ControladorDeProjetos38[[#This Row],[Real Início]] -> 156 | M8: Aprovado | N8: Concluido
A9: APRO | B9: Villa Bella - 59.226 / 2024 | C9: Anuência Prévia para IAP - Versão 05 | D9: Prefeitura Toledo | E9: Michael | F9: 45622 | G9: 45652 | H9: =IF(COUNTA('Prot. TLD - Villa Bella I'!$F9,'Prot. TLD - Villa Bella I'!$G9)<>2,"",DAYS360('Prot. TLD - Villa Bella I'!$F9,'Prot. TLD - Villa Bella I'!$G9,FALSE)) -> 30 | I9: 45622 | J9: 45664 | K9: =IFERROR(IF(ControladorDeProjetos38[[#This Row],[Duração Real (em dias)]]=0,"",IF(ABS((ControladorDeProjetos38[[#This Row],[Duração Real (em dias)]]-ControladorDeProjetos38[[#This Row],[Duração Estimada (em dias)]])/ControladorDeProjetos38[[#This Row],[Duração Estimada (em dias)]])>Sinalizador_Porcentagem,1,0)),"") -> 1 | L9: =ControladorDeProjetos38[[#This Row],[Real Término]]-ControladorDeProjetos38[[#This Row],[Real Início]] -> 42 | N9: Concluido
A10: APRO | B10: Villa Bella - 59.238 / 2024 | C10: Solicitação de Unificação de Lotes - Versão 03 CPF: 060.525.989-56 | D10: Prefeitura Toledo | E10: Michael | F10: 45622 | G10: 45652 | H10: =IF(COUNTA('Prot. TLD - Villa Bella I'!$F10,'Prot. TLD - Villa Bella I'!$G10)<>2,"",DAYS360('Prot. TLD - Villa Bella I'!$F10,'Prot. TLD - Villa Bella I'!$G10,FALSE)) -> 30 | I10: 45622 | J10: 45639 | K10: =IFERROR(IF(ControladorDeProjetos38[[#This Row],[Duração Real (em dias)]]=0,"",IF(ABS((ControladorDeProjetos38[[#This Row],[Duração Real (em dias)]]-ControladorDeProjetos38[[#This Row],[Duração Estimada (em dias)]])/ControladorDeProjetos38[[#This Row],[Duração Estimada (em dias)]])>Sinalizador_Porcentagem,1,0)),"") -> 1 | L10: =ControladorDeProjetos38[[#This Row],[Real Término]]-ControladorDeProjetos38[[#This Row],[Real Início]] -> 17 | N10: Concluido
A11: APRO | B11: Villa Bella - 338.851 / 2024 | C11: Escritura Pública de Doação | D11: Cartório Reg. Imóveis | E11: Michael | F11: 45628 | G11: 45659 | H11: =IF(COUNTA('Prot. TLD - Villa Bella I'!$F11,'Prot. TLD - Villa Bella I'!$G11)<>2,"",DAYS360('Prot. TLD - Villa Bella I'!$F11,'Prot. TLD - Villa Bella I'!$G11,FALSE)) -> 30 | I11: 45628 | J11: 45664 | K11: =IFERROR(IF(ControladorDeProjetos38[[#This Row],[Duração Real (em dias)]]=0,"",IF(ABS((ControladorDeProjetos38[[#This Row],[Duração Real (em dias)]]-ControladorDeProjetos38[[#This Row],[Duração Estimada (em dias)]])/ControladorDeProjetos38[[#This Row],[Duração Estimada (em dias)]])>Sinalizador_Porcentagem,1,0)),"") -> 1 | L11: =ControladorDeProjetos38[[#This Row],[Real Término]]-ControladorDeProjetos38[[#This Row],[Real Início]] -> 36 | N11: Concluido
A12: APRO | B12: Villa Bella - 23.177.759-8 | C12: Licenciamento Ambiental | D12: IAT | E12: Michael | F12: 45664 | G12: 45695 | H12: =IF(COUNTA('Prot. TLD - Villa Bella I'!$F12,'Prot. TLD - Villa Bella I'!$G12)<>2,"",DAYS360('Prot. TLD - Villa Bella I'!$F12,'Prot. TLD - Villa Bella I'!$G12,FALSE)) -> 30 | I12: 45664 | K12: =IFERROR(IF(ControladorDeProjetos38[[#This Row],[Duração Real (em dias)]]=0,"",IF(ABS((ControladorDeProjetos38[[#This Row],[Duração Real (em dias)]]-ControladorDeProjetos38[[#This Row],[Duração Estimada (em dias)]])/ControladorDeProjetos38[[#This Row],[Duração Estimada (em dias)]])>Sinalizador_Porcentagem,1,0)),"") -> 1 | L12: =ControladorDeProjetos38[[#This Row],[Real Término]]-ControladorDeProjetos38[[#This Row],[Real Início]] -> -45664 | N12: Encaminhado
A13: APRO | B13: Villa Bella - 073-001351 / 2025 | C13: Aprovação de Projeto Villa Bella I | D13: Prefeitura Toledo | E13: Michael | F13: 45667 | G13: =ControladorDeProjetos38[[#This Row],[Estimado Início]]+30 -> 45697 | H13: =IF(COUNTA('Prot. TLD - Villa Bella I'!$F13,'Prot. TLD - Villa Bella I'!$G13)<>2,"",DAYS360('Prot. TLD - Villa Bella I'!$F13,'Prot. TLD - Villa Bella I'!$G13,FALSE)) -> 29 | I13: 45667 | J13: 45743 | K13: =IFERROR(IF(ControladorDeProjetos38[[#This Row],[Duração Real (em dias)]]=0,"",IF(ABS((ControladorDeProjetos38[[#This Row],[Duração Real (em dias)]]-ControladorDeProjetos38[[#This Row],[Duração Estimada (em dias)]])/ControladorDeProjetos38[[#This Row],[Duração Estimada (em dias)]])>Sinalizador_Porcentagem,1,0)),"") -> 1 | L13: =ControladorDeProjetos38[[#This Row],[Real Término]]-ControladorDeProjetos38[[#This Row],[Real Início]] -> 76 | N13: Concluido
A14: CANC | B14: 20258808646103 | C14: Aprovação de projeto de medição elétrica | D14: Copel | E14: Rodrigo | F14: 45730 | G14: 45762 | H14: =IF(COUNTA('Prot. TLD - Villa Bella I'!$F14,'Prot. TLD - Villa Bella I'!$G14)<>2,"",DAYS360('Prot. TLD - Villa Bella I'!$F14,'Prot. TLD - Villa Bella I'!$G14,FALSE)) -> 31 | I14: 45730 | K14: =IFERROR(IF(ControladorDeProjetos38[[#This Row],[Duração Real (em dias)]]=0,"",IF(ABS((ControladorDeProjetos38[[#This Row],[Duração Real (em dias)]]-ControladorDeProjetos38[[#This Row],[Duração Estimada (em dias)]])/ControladorDeProjetos38[[#This Row],[Duração Estimada (em dias)]])>Sinalizador_Porcentagem,1,0)),"") -> 1 | L14: =ControladorDeProjetos38[[#This Row],[Real Término]]-ControladorDeProjetos38[[#This Row],[Real Início]] -> -45730 | M14: Atendido dia 07/04 | N14: Encaminhado
A15: ANÁL | B15: 23.685.993-2 | C15: Corpo de bombeiros | D15: Corpo de Bombeiros | E15: Rodrigo | F15: 45735 | G15: =ControladorDeProjetos38[[#This Row],[Estimado Início]]+30 -> 45765 | H15: =IF(COUNTA('Prot. TLD - Villa Bella I'!$F15,'Prot. TLD - Villa Bella I'!$G15)<>2,"",DAYS360('Prot. TLD - Villa Bella I'!$F15,'Prot. TLD - Villa Bella I'!$G15,FALSE)) -> 29 | I15: 45735 | K15: =IFERROR(IF(ControladorDeProjetos38[[#This Row],[Duração Real (em dias)]]=0,"",IF(ABS((ControladorDeProjetos38[[#This Row],[Duração Real (em dias)]]-ControladorDeProjetos38[[#This Row],[Duração Estimada (em dias)]])/ControladorDeProjetos38[[#This Row],[Duração Estimada (em dias)]])>Sinalizador_Porcentagem,1,0)),"") -> 1 | L15: =ControladorDeProjetos38[[#This Row],[Real Término]]-ControladorDeProjetos38[[#This Row],[Real Início]] -> -45735 | N15: Encaminhado
A16: CANC | B16: 344147 | C16: Registro da Incorporação de condomínio | D16: Cartório Reg. Imóveis | E16: Rodrigo | F16: 45744 | G16: =ControladorDeProjetos38[[#This Row],[Estimado Início]]+20 -> 45764 | H16: =IF(COUNTA('Prot. TLD - Villa Bella I'!$F16,'Prot. TLD - Villa Bella I'!$G16)<>2,"",DAYS360('Prot. TLD - Villa Bella I'!$F16,'Prot. TLD - Villa Bella I'!$G16,FALSE)) -> 19 | I16: 45744 | K16: =IFERROR(IF(ControladorDeProjetos38[[#This Row],[Duração Real (em dias)]]=0,"",IF(ABS((ControladorDeProjetos38[[#This Row],[Duração Real (em dias)]]-ControladorDeProjetos38[[#This Row],[Duração Estimada (em dias)]])/ControladorDeProjetos38[[#This Row],[Duração Estimada (em dias)]])>Sinalizador_Porcentagem,1,0)),"") -> 1 | L16: =ControladorDeProjetos38[[#This Row],[Real Término]]-ControladorDeProjetos38[[#This Row],[Real Início]] -> -45744 | M16: 18/06 - diligencias / assinaturas | N16: Encaminhado
A17: CANC | B17: 344146 | C17: Escritura Pública de Permuta | D17: Cartório Reg. Imóveis | E17: Rodrigo | F17: 45744 | G17: =ControladorDeProjetos38[[#This Row],[Estimado Início]]+20 -> 45764 | H17: =IF(COUNTA('Prot. TLD - Villa Bella I'!$F17,'Prot. TLD - Villa Bella I'!$G17)<>2,"",DAYS360('Prot. TLD - Villa Bella I'!$F17,'Prot. TLD - Villa Bella I'!$G17,FALSE)) -> 19 | I17: 45744 | K17: =IFERROR(IF(ControladorDeProjetos38[[#This Row],[Duração Real (em dias)]]=0,"",IF(ABS((ControladorDeProjetos38[[#This Row],[Duração Real (em dias)]]-ControladorDeProjetos38[[#This Row],[Duração Estimada (em dias)]])/ControladorDeProjetos38[[#This Row],[Duração Estimada (em dias)]])>Sinalizador_Porcentagem,1,0)),"") -> 1 | L17: =ControladorDeProjetos38[[#This Row],[Real Término]]-ControladorDeProjetos38[[#This Row],[Real Início]] -> -45744 | M17: 18/06 - diligencias / exigencias
A18: CANC | B18: 20259119627173 | C18: Aprovação de projeto de medição elétrica | D18: Copel | E18: Rodrigo | F18: 45771 | G18: 45803 | H18: =IF(COUNTA('Prot. TLD - Villa Bella I'!$F18,'Prot. TLD - Villa Bella I'!$G18)<>2,"",DAYS360('Prot. TLD - Villa Bella I'!$F18,'Prot. TLD - Villa Bella I'!$G18,FALSE)) -> 32 | I18: 45730 | K18: =IFERROR(IF(ControladorDeProjetos38[[#This Row],[Duração Real (em dias)]]=0,"",IF(ABS((ControladorDeProjetos38[[#This Row],[Duração Real (em dias)]]-ControladorDeProjetos38[[#This Row],[Duração Estimada (em dias)]])/ControladorDeProjetos38[[#This Row],[Duração Estimada (em dias)]])>Sinalizador_Porcentagem,1,0)),"") -> 1 | L18: =ControladorDeProjetos38[[#This Row],[Real Término]]-ControladorDeProjetos38[[#This Row],[Real Início]] -> -45730
A19: APRO | B19: 20259333369822 | C19: Aprovação de projeto de medição elétrica | D19: Copel | E19: Rodrigo | F19: 45766 | G19: =ControladorDeProjetos38[[#This Row],[Estimado Início]]+30 -> 45796 | H19: =IF(COUNTA('Prot. TLD - Villa Bella I'!$F19,'Prot. TLD - Villa Bella I'!$G19)<>2,"",DAYS360('Prot. TLD - Villa Bella I'!$F19,'Prot. TLD - Villa Bella I'!$G19,FALSE)) -> 30 | I19: 45730 | J19: 45861 | K19: =IFERROR(IF(ControladorDeProjetos38[[#This Row],[Duração Real (em dias)]]=0,"",IF(ABS((ControladorDeProjetos38[[#This Row],[Duração Real (em dias)]]-ControladorDeProjetos38[[#This Row],[Duração Estimada (em dias)]])/ControladorDeProjetos38[[#This Row],[Duração Estimada (em dias)]])>Sinalizador_Porcentagem,1,0)),"") -> 1 | L19: =ControladorDeProjetos38[[#This Row],[Real Término]]-ControladorDeProjetos38[[#This Row],[Real Início]] -> 131
A20: APRO | B20: 20259459823693 (20259901871675) | C20: Solicitação de Fornecimento de Energia | D20: Copel | E20: Rodrigo | F20: 45811 | G20: 45813 | H20: =IF(COUNTA('Prot. TLD - Villa Bella I'!$F20,'Prot. TLD - Villa Bella I'!$G20)<>2,"",DAYS360('Prot. TLD - Villa Bella I'!$F20,'Prot. TLD - Villa Bella I'!$G20,FALSE)) -> 2 | I20: 45811 | J20: 45861 | K20: =IFERROR(IF(ControladorDeProjetos38[[#This Row],[Duração Real (em dias)]]=0,"",IF(ABS((ControladorDeProjetos38[[#This Row],[Duração Real (em dias)]]-ControladorDeProjetos38[[#This Row],[Duração Estimada (em dias)]])/ControladorDeProjetos38[[#This Row],[Duração Estimada (em dias)]])>Sinalizador_Porcentagem,1,0)),"") -> 1 | L20: =ControladorDeProjetos38[[#This Row],[Real Término]]-ControladorDeProjetos38[[#This Row],[Real Início]] -> 50 | M20: Previsão de entrega do orçamento 03/07/2025
A21: APRO | B21: 345242 | C21: Escritura pública de permuta | D21: Cartório Reg. Imóveis | E21: Rodrigo | F21: 45826 | G21: 45841 | H21: =IF(COUNTA('Prot. TLD - Villa Bella I'!$F21,'Prot. TLD - Villa Bella I'!$G21)<>2,"",DAYS360('Prot. TLD - Villa Bella I'!$F21,'Prot. TLD - Villa Bella I'!$G21,FALSE)) -> 15 | I21: 45826 | J21: 45846 | K21: =IFERROR(IF(ControladorDeProjetos38[[#This Row],[Duração Real (em dias)]]=0,"",IF(ABS((ControladorDeProjetos38[[#This Row],[Duração Real (em dias)]]-ControladorDeProjetos38[[#This Row],[Duração Estimada (em dias)]])/ControladorDeProjetos38[[#This Row],[Duração Estimada (em dias)]])>Sinalizador_Porcentagem,1,0)),"") -> 1 | L21: =ControladorDeProjetos38[[#This Row],[Real Término]]-ControladorDeProjetos38[[#This Row],[Real Início]] -> 20
A22: APRO | B22: 345244 | C22: Registro da Incorporação de condomínio | D22: Cartório Reg. Imóveis | E22: Rodrigo | F22: 45826 | G22: 45841 | H22: =IF(COUNTA('Prot. TLD - Villa Bella I'!$F22,'Prot. TLD - Villa Bella I'!$G22)<>2,"",DAYS360('Prot. TLD - Villa Bella I'!$F22,'Prot. TLD - Villa Bella I'!$G22,FALSE)) -> 15 | I22: 45826 | J22: 45846 | K22: =IFERROR(IF(ControladorDeProjetos38[[#This Row],[Duração Real (em dias)]]=0,"",IF(ABS((ControladorDeProjetos38[[#This Row],[Duração Real (em dias)]]-ControladorDeProjetos38[[#This Row],[Duração Estimada (em dias)]])/ControladorDeProjetos38[[#This Row],[Duração Estimada (em dias)]])>Sinalizador_Porcentagem,1,0)),"") -> 1 | L22: =ControladorDeProjetos38[[#This Row],[Real Término]]-ControladorDeProjetos38[[#This Row],[Real Início]] -> 20
A23: CANC | B23: 24126299 | C23: Corte de árvores isoladas | D23: IAT | E23: Rodrigo | F23: 45854 | G23: =F23+45 -> 45899 | H23: =IF(COUNTA('Prot. TLD - Villa Bella I'!$F23,'Prot. TLD - Villa Bella I'!$G23)<>2,"",DAYS360('Prot. TLD - Villa Bella I'!$F23,'Prot. TLD - Villa Bella I'!$G23,FALSE)) -> 44 | I23: 45854 | K23: =IFERROR(IF(ControladorDeProjetos38[[#This Row],[Duração Real (em dias)]]=0,"",IF(ABS((ControladorDeProjetos38[[#This Row],[Duração Real (em dias)]]-ControladorDeProjetos38[[#This Row],[Duração Estimada (em dias)]])/ControladorDeProjetos38[[#This Row],[Duração Estimada (em dias)]])>Sinalizador_Porcentagem,1,0)),"") | L23: =ControladorDeProjetos38[[#This Row],[Real Término]]-ControladorDeProjetos38[[#This Row],[Real Início]] -> #VALUE!
A24: CANC | B24: 33869 / 2025 | C24: Certidão de uso do solo | D24: Prefeitura Toledo | E24: Eduarda | F24: 45860 | G24: 45876 | H24: =IF(COUNTA('Prot. TLD - Villa Bella I'!$F24,'Prot. TLD - Villa Bella I'!$G24)<>2,"",DAYS360('Prot. TLD - Villa Bella I'!$F24,'Prot. TLD - Villa Bella I'!$G24,FALSE)) -> 15 | I24: 45860 | K24: =IFERROR(IF(ControladorDeProjetos38[[#This Row],[Duração Real (em dias)]]=0,"",IF(ABS((ControladorDeProjetos38[[#This Row],[Duração Real (em dias)]]-ControladorDeProjetos38[[#This Row],[Duração Estimada (em dias)]])/ControladorDeProjetos38[[#This Row],[Duração Estimada (em dias)]])>Sinalizador_Porcentagem,1,0)),"") | L24: =ControladorDeProjetos38[[#This Row],[Real Término]]-ControladorDeProjetos38[[#This Row],[Real Início]] -> #VALUE!
A25: APRO | B25: 24.269.948-3 | C25: Protocolo sanepar | D25: Sanepar | E25: Cristian | F25: 45846 | G25: 45888 | H25: =IF(COUNTA('Prot. TLD - Villa Bella I'!$F25,'Prot. TLD - Villa Bella I'!$G25)<>2,"",DAYS360('Prot. TLD - Villa Bella I'!$F25,'Prot. TLD - Villa Bella I'!$G25,FALSE)) -> 41 | I25: 45846 | K25: =IFERROR(IF(ControladorDeProjetos38[[#This Row],[Duração Real (em dias)]]=0,"",IF(ABS((ControladorDeProjetos38[[#This Row],[Duração Real (em dias)]]-ControladorDeProjetos38[[#This Row],[Duração Estimada (em dias)]])/ControladorDeProjetos38[[#This Row],[Duração Estimada (em dias)]])>Sinalizador_Porcentagem,1,0)),"") | L25: =ControladorDeProjetos38[[#This Row],[Real Término]]-ControladorDeProjetos38[[#This Row],[Real Início]] -> #VALUE!
A26: APRO | B26: 43194 / 2025 | C26: Ativação de cadastro V.B. 1 | D26: Prefeitura Toledo | E26: Eduarda | F26: 45905 | G26: =F26+15 -> 45920 | H26: =IF(COUNTA('Prot. TLD - Villa Bella I'!$F26,'Prot. TLD - Villa Bella I'!$G26)<>2,"",DAYS360('Prot. TLD - Villa Bella I'!$F26,'Prot. TLD - Villa Bella I'!$G26,FALSE)) -> 15 | I26: 45905 | K26: =IFERROR(IF(ControladorDeProjetos38[[#This Row],[Duração Real (em dias)]]=0,"",IF(ABS((ControladorDeProjetos38[[#This Row],[Duração Real (em dias)]]-ControladorDeProjetos38[[#This Row],[Duração Estimada (em dias)]])/ControladorDeProjetos38[[#This Row],[Duração Estimada (em dias)]])>Sinalizador_Porcentagem,1,0)),"")
A27: APRO | B27: 353321 | C27: Requerimento Servidão de Passagem | D27: Cartório Reg. Imóveis | E27: Eduarda | F27: 46057 | G27: 46073 | H27: =IF(COUNTA('Prot. TLD - Villa Bella I'!$F27,'Prot. TLD - Villa Bella I'!$G27)<>2,"",DAYS360('Prot. TLD - Villa Bella I'!$F27,'Prot. TLD - Villa Bella I'!$G27,FALSE)) -> 16 | I27: 46057 | J27: 46099 | K27: =IFERROR(IF(ControladorDeProjetos367314[[#This Row],[Duração Real (em dias)]]=0,"",IF(ABS((ControladorDeProjetos367314[[#This Row],[Duração Real (em dias)]]-ControladorDeProjetos367314[[#This Row],[Duração Estimada (em dias)]])/ControladorDeProjetos367314[[#This Row],[Duração Estimada (em dias)]])>Sinalizador_Porcentagem,1,0)),"") | L27: =IF(COUNTA('Prot. CVEL - Bella Citta'!$I27,'Prot. CVEL - Bella Citta'!$J27)<>2,"",DAYS360('Prot. CVEL - Bella Citta'!$I27,'Prot. CVEL - Bella Citta'!$J27,FALSE))
A28: ANÁL | B28: 10140 / 2026 | C28: Drenagem | D28: Prefeitura Toledo | E28: Lavinia | F28: 46079 | G28: 46107 | H28: =IF(COUNTA('Prot. TLD - Villa Bella I'!$F28,'Prot. TLD - Villa Bella I'!$G28)<>2,"",DAYS360('Prot. TLD - Villa Bella I'!$F28,'Prot. TLD - Villa Bella I'!$G28,FALSE)) -> 30 | I28: 46079 | K28: =IFERROR(IF(ControladorDeProjetos367314[[#This Row],[Duração Real (em dias)]]=0,"",IF(ABS((ControladorDeProjetos367314[[#This Row],[Duração Real (em dias)]]-ControladorDeProjetos367314[[#This Row],[Duração Estimada (em dias)]])/ControladorDeProjetos367314[[#This Row],[Duração Estimada (em dias)]])>Sinalizador_Porcentagem,1,0)),"") | L28: =IF(COUNTA('Prot. CVEL - Bella Citta'!$I28,'Prot. CVEL - Bella Citta'!$J28)<>2,"",DAYS360('Prot. CVEL - Bella Citta'!$I28,'Prot. CVEL - Bella Citta'!$J28,FALSE))

Sheet Prot. TLD - Villa Bella II
A1: Controlador De Protocolos Villa Bella II - Toledo | E1: CNPJ PRATI: | F1: 35.538.973/0001-63 | I1: #VALUE!
C2: Sinalizador de Porcentagem Acima/Abaixo: | E2: CNPJ VILLA BELLA: | F2: 57.740.735/0001-79
E3: CPF RODRIGO | F3: 078.910.009-64
A4: Status | B4: Projeto + Protocolo | C4: Atividade | D4: Aprovações | E4: Atribuída a | F4: Estimado Início | G4: Estimado Término | H4: Duração Estimada (em dias) | I4: Real Início | J4: Real Término | K4: Sinalizador para duração real acima/abaixo (em dias)S | L4: Duração Real (em dias) | M4: Anotações | N4: Situação
A5: APRO | B5: Villa Bella II -073-001667 / 2025 | C5: Aprovação de Projeto Villa Bella II | D5: Prefeitura Toledo | E5: Rodrigo | F5: 45706 | G5: 45767 | H5: =IF(COUNTA('Prot. TLD - Villa Bella I'!$F13,'Prot. TLD - Villa Bella I'!$G13)<>2,"",DAYS360('Prot. TLD - Villa Bella I'!$F13,'Prot. TLD - Villa Bella I'!$G13,FALSE)) -> 29 | K5: =IFERROR(IF(ControladorDeProjetos38[[#This Row],[Duração Real (em dias)]]=0,"",IF(ABS((ControladorDeProjetos38[[#This Row],[Duração Real (em dias)]]-ControladorDeProjetos38[[#This Row],[Duração Estimada (em dias)]])/ControladorDeProjetos38[[#This Row],[Duração Estimada (em dias)]])>Sinalizador_Porcentagem,1,0)),"") -> 1 | L5: =ControladorDeProjetos38[[#This Row],[Real Término]]-ControladorDeProjetos38[[#This Row],[Real Início]] -> 70 | M5: Acompanhar pelo email | N5: Encaminhado
A6: APRO | B6: 18047/2025 | C6: EIV Villa Bella II - CNPJ: 57.740.735/0001-79 | D6: Prefeitura Toledo | E6: Rodrigo | H6: =IF(COUNTA('Prot. TLD - Villa Bella I'!$F14,'Prot. TLD - Villa Bella I'!$G14)<>2,"",DAYS360('Prot. TLD - Villa Bella I'!$F14,'Prot. TLD - Villa Bella I'!$G14,FALSE)) -> 31 | K6: =IFERROR(IF(ControladorDeProjetos38[[#This Row],[Duração Real (em dias)]]=0,"",IF(ABS((ControladorDeProjetos38[[#This Row],[Duração Real (em dias)]]-ControladorDeProjetos38[[#This Row],[Duração Estimada (em dias)]])/ControladorDeProjetos38[[#This Row],[Duração Estimada (em dias)]])>Sinalizador_Porcentagem,1,0)),"") -> 1 | L6: =ControladorDeProjetos38[[#This Row],[Real Término]]-ControladorDeProjetos38[[#This Row],[Real Início]] -> 40 | M6: Aprovação de projetos
A7: APRO | B7: 346063 | C7: Escritura Pública de Permuta | D7: Cartório Reg. Imóveis | E7: Eduarda | F7: 45849 | G7: 45863 | H7: =G7-F7 -> 14 | I7: 45849 | K7: =IFERROR(IF(ControladorDeProjetos38[[#This Row],[Duração Real (em dias)]]=0,"",IF(ABS((ControladorDeProjetos38[[#This Row],[Duração Real (em dias)]]-ControladorDeProjetos38[[#This Row],[Duração Estimada (em dias)]])/ControladorDeProjetos38[[#This Row],[Duração Estimada (em dias)]])>Sinalizador_Porcentagem,1,0)),"") -> 1 | M7: Enca | N7: Encaminhado
A8: APRO | B8: 346065 | C8: Incorporação de Condomínio | D8: Cartório Reg. Imóveis | E8: Eduarda | F8: 45849 | G8: 45863 | H8: =G8-F8 -> 14 | I8: 45849 | K8: =IFERROR(IF(ControladorDeProjetos38[[#This Row],[Duração Real (em dias)]]=0,"",IF(ABS((ControladorDeProjetos38[[#This Row],[Duração Real (em dias)]]-ControladorDeProjetos38[[#This Row],[Duração Estimada (em dias)]])/ControladorDeProjetos38[[#This Row],[Duração Estimada (em dias)]])>Sinalizador_Porcentagem,1,0)),"") -> 1 | N8: Encaminhado
A9: APRO | B9: 309448 | C9: certidão vintenaria | D9: Cartório Reg. Imóveis | E9: Rodrigo | F9: 45875 | G9: 45882 | H9: =IF(COUNTA('Prot. TLD - Villa Bella II'!$F9,'Prot. TLD - Villa Bella II'!$G9)<>2,"",DAYS360('Prot. TLD - Villa Bella II'!$F9,'Prot. TLD - Villa Bella II'!$G9,FALSE)) -> 7 | I9: 45875 | K9: =IFERROR(IF(ControladorDeProjetos369[[#This Row],[Duração Real (em dias)]]=0,"",IF(ABS((ControladorDeProjetos369[[#This Row],[Duração Real (em dias)]]-ControladorDeProjetos369[[#This Row],[Duração Estimada (em dias)]])/ControladorDeProjetos369[[#This Row],[Duração Estimada (em dias)]])>Sinalizador_Porcentagem,1,0)),"") -> 0 | L9: =ControladorDeProjetos369[[#This Row],[Real Término]]-ControladorDeProjetos369[[#This Row],[Real Início]] -> 7
A10: APRO | B10: 24.301.139-6 | C10: Carta de viabilidade | D10: Sanepar | E10: Cristian | F10: 45849 | G10: 45891 | H10: =IF(COUNTA('Prot. TLD - Villa Bella II'!$F10,'Prot. TLD - Villa Bella II'!$G10)<>2,"",DAYS360('Prot. TLD - Villa Bella II'!$F10,'Prot. TLD - Villa Bella II'!$G10,FALSE)) -> 41 | I10: 45849 | J10: 45903 | K10: =IFERROR(IF(ControladorDeProjetos38[[#This Row],[Duração Real (em dias)]]=0,"",IF(ABS((ControladorDeProjetos38[[#This Row],[Duração Real (em dias)]]-ControladorDeProjetos38[[#This Row],[Duração Estimada (em dias)]])/ControladorDeProjetos38[[#This Row],[Duração Estimada (em dias)]])>Sinalizador_Porcentagem,1,0)),"") -> 1 | M10: Pedido carta de viabilidade | N10: Aprovado
A11: APRO | B11: 43196 / 2025 | C11: Ativação de cadastro V.B. 2 | D11: Prefeitura Toledo | E11: Rodrigo | F11: 45905 | G11: =F11+15 -> 45920 | H11: 15 | I11: 45905 | K11: =IFERROR(IF(ControladorDeProjetos38[[#This Row],[Duração Real (em dias)]]=0,"",IF(ABS((ControladorDeProjetos38[[#This Row],[Duração Real (em dias)]]-ControladorDeProjetos38[[#This Row],[Duração Estimada (em dias)]])/ControladorDeProjetos38[[#This Row],[Duração Estimada (em dias)]])>Sinalizador_Porcentagem,1,0)),"") -> 1 | N11: Protocolado

Sheet Prot. TLD - Carmel
A1: Controlador De Protocolos Empreendimento Carmel - Toledo
C2: Sinalizador de Porcentagem Acima/Abaixo: | I2: CNPJ CARMEL | J2: 59.387.026/0001-87
A4: Status | B4: Projeto + Protocolo | C4: Atividade | D4: Aprovações | E4: Atribuída a | F4: Estimado Início | G4: Estimado Término | H4: Duração Estimada (em dias) | I4: Real Início | J4: Real Término | K4: Sinalizador para duração real acima/abaixo (em dias)S | L4: Duração Real (em dias) | M4: Anotações | N4: Situação
A5: CANC | B5: Carmel - 339.058 / 2024 | C5: Escritura Pública de Compra e Venda | D5: Cartório Reg. Imóveis | E5: Michael | F5: 45632 | G5: 45639 | H5: =IF(COUNTA('Prot. TLD - Carmel'!$F5,'Prot. TLD - Carmel'!$G5)<>2,"",DAYS360('Prot. TLD - Carmel'!$F5,'Prot. TLD - Carmel'!$G5,FALSE)) -> 7 | I5: 45632 | J5: 45667 | K5: =IFERROR(IF(ControladorDeProjetos369[[#This Row],[Duração Real (em dias)]]=0,"",IF(ABS((ControladorDeProjetos369[[#This Row],[Duração Real (em dias)]]-ControladorDeProjetos369[[#This Row],[Duração Estimada (em dias)]])/ControladorDeProjetos369[[#This Row],[Duração Estimada (em dias)]])>Sinalizador_Porcentagem,1,0)),"") -> 1 | L5: =ControladorDeProjetos369[[#This Row],[Real Término]]-ControladorDeProjetos369[[#This Row],[Real Início]] -> 35 | N5: Cancelado
A6: CANC | B6: Carmel - 339.059 / 2024 | C6: Requerimento de Averbação da Unificação | D6: Cartório Reg. Imóveis | E6: Michael | F6: 45632 | G6: 45646 | H6: =IF(COUNTA('Prot. TLD - Carmel'!$F6,'Prot. TLD - Carmel'!$G6)<>2,"",DAYS360('Prot. TLD - Carmel'!$F6,'Prot. TLD - Carmel'!$G6,FALSE)) -> 14 | I6: 45632 | J6: 45667 | L6: =ControladorDeProjetos369[[#This Row],[Real Término]]-ControladorDeProjetos369[[#This Row],[Real Início]] -> 35 | N6: Cancelado
A7: APRO | B7: Carmel - 340.165 / 2025 | C7: 339.058 / pt2 | D7: Cartório Reg. Imóveis | E7: Michael | F7: 45671 | G7: 45678 | H7: =IF(COUNTA('Prot. TLD - Carmel'!$F7,'Prot. TLD - Carmel'!$G7)<>2,"",DAYS360('Prot. TLD - Carmel'!$F7,'Prot. TLD - Carmel'!$G7,FALSE)) -> 7 | I7: 45671 | J7: 45678 | L7: =ControladorDeProjetos369[[#This Row],[Real Término]]-ControladorDeProjetos369[[#This Row],[Real Início]] -> 7 | N7: Finalizado
A8: APRO | B8: Carmel - 340.166 / 2025 | C8: pt2 | D8: Cartório Reg. Imóveis | E8: Michael | F8: 45671 | G8: 45685 | H8: =IF(COUNTA('Prot. TLD - Carmel'!$F8,'Prot. TLD - Carmel'!$G8)<>2,"",DAYS360('Prot. TLD - Carmel'!$F8,'Prot. TLD - Carmel'!$G8,FALSE)) -> 14 | I8: 45671 | J8: 45678 | L8: =ControladorDeProjetos369[[#This Row],[Real Término]]-ControladorDeProjetos369[[#This Row],[Real Início]] -> 7 | N8: Finalizado
A9: APRO | B9: Carmel - 340.167 / 2025 | C9: 339.059 / pt2 | D9: Cartório Reg. Imóveis | E9: Michael | F9: 45671 | G9: 45678 | H9: =IF(COUNTA('Prot. TLD - Carmel'!$F9,'Prot. TLD - Carmel'!$G9)<>2,"",DAYS360('Prot. TLD - Carmel'!$F9,'Prot. TLD - Carmel'!$G9,FALSE)) -> 7 | I9: 45671 | J9: 45678 | L9: =ControladorDeProjetos369[[#This Row],[Real Término]]-ControladorDeProjetos369[[#This Row],[Real Início]] -> 7 | N9: Finalizado
A10: APRO | B10: Carmel 20258398330847 | C10: Medição | D10: Copel | E10: Michael | F10: 45680 | G10: 45711 | H10: =IF(COUNTA('Prot. TLD - Carmel'!$F10,'Prot. TLD - Carmel'!$G10)<>2,"",DAYS360('Prot. TLD - Carmel'!$F10,'Prot. TLD - Carmel'!$G10,FALSE)) -> 30 | I10: 45680 | J10: 45685 | L10: =ControladorDeProjetos369[[#This Row],[Real Término]]-ControladorDeProjetos369[[#This Row],[Real Início]] -> 5 | N10: Finalizado
A11: APRO | B11: 20258677359583 | C11: Solicitação carta de viabilidade | D11: Copel | E11: Rodrigo | F11: 45715 | G11: 45747 | H11: =IF(COUNTA('Prot. TLD - Carmel'!$F11,'Prot. TLD - Carmel'!$G11)<>2,"",DAYS360('Prot. TLD - Carmel'!$F11,'Prot. TLD - Carmel'!$G11,FALSE)) -> 34 | I11: 45715 | J11: 45719 | K11: =IFERROR(IF(ControladorDeProjetos369[[#This Row],[Duração Real (em dias)]]=0,"",IF(ABS((ControladorDeProjetos369[[#This Row],[Duração Real (em dias)]]-ControladorDeProjetos369[[#This Row],[Duração Estimada (em dias)]])/ControladorDeProjetos369[[#This Row],[Duração Estimada (em dias)]])>Sinalizador_Porcentagem,1,0)),"") -> 1 | L11: =ControladorDeProjetos369[[#This Row],[Real Término]]-ControladorDeProjetos369[[#This Row],[Real Início]] -> 4 | N11: Finalizado
A12: CANC | B12: 089-001941-2025 | C12: Análise prévia urbana (EIV) | D12: Prefeitura Toledo | E12: Rodrigo | F12: 45744 | G12: =ControladorDeProjetos369[[#This Row],[Estimado Início]]+30 -> 45774 | H12: =IF(COUNTA('Prot. TLD - Carmel'!$F12,'Prot. TLD - Carmel'!$G12)<>2,"",DAYS360('Prot. TLD - Carmel'!$F12,'Prot. TLD - Carmel'!$G12,FALSE)) -> 29 | I12: 45747 | J12: 45761 | K12: =IFERROR(IF(ControladorDeProjetos369[[#This Row],[Duração Real (em dias)]]=0,"",IF(ABS((ControladorDeProjetos369[[#This Row],[Duração Real (em dias)]]-ControladorDeProjetos369[[#This Row],[Duração Estimada (em dias)]])/ControladorDeProjetos369[[#This Row],[Duração Estimada (em dias)]])>Sinalizador_Porcentagem,1,0)),"") -> 1 | L12: =ControladorDeProjetos369[[#This Row],[Real Término]]-ControladorDeProjetos369[[#This Row],[Real Início]] -> 14 | N12: Finalizado
A13: APRO | B13: 18.624 / 2025 | C13: Análise EIV- 59.387.026/0001-87 | D13: Prefeitura Toledo | E13: Eduarda | F13: 45763 | G13: 45793 | H13: =IF(COUNTA('Prot. TLD - Carmel'!$F13,'Prot. TLD - Carmel'!$G13)<>2,"",DAYS360('Prot. TLD - Carmel'!$F13,'Prot. TLD - Carmel'!$G13,FALSE)) -> 30 | I13: 45763 | J13: 46083 | K13: =IFERROR(IF(ControladorDeProjetos369[[#This Row],[Duração Real (em dias)]]=0,"",IF(ABS((ControladorDeProjetos369[[#This Row],[Duração Real (em dias)]]-ControladorDeProjetos369[[#This Row],[Duração Estimada (em dias)]])/ControladorDeProjetos369[[#This Row],[Duração Estimada (em dias)]])>Sinalizador_Porcentagem,1,0)),"") -> 1 | L13: =ControladorDeProjetos369[[#This Row],[Real Término]]-ControladorDeProjetos369[[#This Row],[Real Início]] -> 320
A14: APRO | B14: 073-002070-2025 | C14: Análise projeto arquitetonico | D14: Prefeitura Toledo | E14: Rodrigo | F14: 45756 | G14: =ControladorDeProjetos369[[#This Row],[Estimado Início]]+30 -> 45786 | H14: =IF(COUNTA('Prot. TLD - Carmel'!$F14,'Prot. TLD - Carmel'!$G14)<>2,"",DAYS360('Prot. TLD - Carmel'!$F14,'Prot. TLD - Carmel'!$G14,FALSE)) -> 30 | I14: 45756 | K14: =IFERROR(IF(ControladorDeProjetos369[[#This Row],[Duração Real (em dias)]]=0,"",IF(ABS((ControladorDeProjetos369[[#This Row],[Duração Real (em dias)]]-ControladorDeProjetos369[[#This Row],[Duração Estimada (em dias)]])/ControladorDeProjetos369[[#This Row],[Duração Estimada (em dias)]])>Sinalizador_Porcentagem,1,0)),"") -> 1 | L14: =ControladorDeProjetos369[[#This Row],[Real Término]]-ControladorDeProjetos369[[#This Row],[Real Início]] -> -45756
